Workbook

Sheet Inventario_Sistemas
A1: ID Sistema | B1: Nombre oficial del sistema | C1: Acrónimo | D1: Dependencia / Entidad | E1: Unidad responsable (Dueño del sistema) | F1: Función institucional que soporta | G1: Clasificación del sistema (Crítico/Alto/Medio/Bajo) | H1: Tipo de sistema (Web/Legado/BD/API/Móvil/Otro) | I1: Ambiente principal (Prod/Preprod/Dev/Otro) | J1: Versión actual del sistema | K1: Fecha de última actualización (release productivo) | L1: Lenguaje principal | M1: Framework | N1: Base de datos | O1: Versión de Base de Datos | P1: Sistema Operativo del servidor | Q1: Versión del SO | R1: Web server / App server | S1: ¿Usa componentes open source? | T1: Listado de componentes open source (si aplica) | U1: ¿Tiene componentes EOL (End of Life)? | V1: Fecha fin de soporte fabricante | W1: Score riesgo tecnológico (EOL/Soporte) | X1: URL pública (si aplica) | Y1: IP pública (si aplica) | Z1: ¿Tiene WAF? | AA1: ¿Está detrás de CDN? | AB1: ¿Requiere autenticación? | AC1: Tipo de autenticación (MFA/AD/OAuth/Otro) | AD1: ¿Cuenta con certificado SSL válido? | AE1: Fecha expiración SSL | AF1: ¿Tiene DNSSEC? | AG1: ¿SPF/DKIM/DMARC configurado? | AH1: ¿Expuesto a Internet? | AI1: Puertos abiertos (si aplica) | AJ1: ¿Escaneo reciente de vulnerabilidades? | AK1: Fecha último escaneo | AL1: Vulnerabilidades críticas abiertas (número) | AM1: Score exposición | AN1: Tipo de infraestructura (On-prem/Nube pública/Híbrido) | AO1: Proveedor nube (AWS/Azure/GCP/Nacional/N/A) | AP1: ¿Infraestructura compartida? | AQ1: ¿Segmentación de red? | AR1: ¿Microsegmentación? | AS1: ¿Reside en infraestructura crítica? | AT1: ¿Tiene respaldo automatizado? | AU1: Frecuencia de respaldos (Diario/Semanal/Mensual) | AV1: RTO (horas) | AW1: RPO (horas) | AX1: ¿Replica en sitio alterno? | AY1: Score respaldo | AZ1: ¿Integrado a AD institucional? | BA1: ¿Tiene MFA habilitado? | BB1: ¿Control de accesos basado en roles (RBAC)? | BC1: ¿Cuenta con PAM? | BD1: Número de usuarios activos | BE1: Número de cuentas privilegiadas | BF1: ¿Revisión periódica de accesos? | BG1: Última revisión de accesos (AAAA-MM-DD) | BH1: Score identidad/accesos (MFA) | BI1: ¿EDR instalado en servidor? | BJ1: ¿Logs enviados a SIEM? | BK1: ¿Monitoreado por SOC? | BL1: ¿Pruebas de penetración realizadas? | BM1: Fecha último pentest | BN1: ¿Hardening aplicado? | BO1: Baseline aplicado | BP1: ¿Plan de continuidad documentado? | BQ1: Score vulnerabilidades | BR1: Score total automático (ponderado) | BS1: Nivel de riesgo (Crítico/Alto/Medio/Bajo) | BT1: Declaratoria de veracidad (Sí/No)
W2: =IF(U2="Sí",5,IF(AND(V2<>"",V2<=TODAY()),5,3)) -> 3 | AM2: =IF(AH2="Sí",5,2) -> 2 | AY2: =IF(AT2="No",5,1) -> 1 | BH2: =IF(BA2="No",5,1) -> 1 | BQ2: =IF(AL2>0,5,1) -> 1 | BR2: =(AM2*0.3+W2*0.25+BH2*0.15+AY2*0.15+BQ2*0.15) -> 1.8 | BS2: =IF(BR2>=4.5,"Crítico",IF(BR2>=3.5,"Alto",IF(BR2>=2.5,"Medio","Bajo"))) -> Bajo
W3: =IF(U3="Sí",5,IF(AND(V3<>"",V3<=TODAY()),5,3)) -> 3 | AM3: =IF(AH3="Sí",5,2) -> 2 | AY3: =IF(AT3="No",5,1) -> 1 | BH3: =IF(BA3="No",5,1) -> 1 | BQ3: =IF(AL3>0,5,1) -> 1 | BR3: =(AM3*0.3+W3*0.25+BH3*0.15+AY3*0.15+BQ3*0.15) -> 1.8 | BS3: =IF(BR3>=4.5,"Crítico",IF(BR3>=3.5,"Alto",IF(BR3>=2.5,"Medio","Bajo"))) -> Bajo
W4: =IF(U4="Sí",5,IF(AND(V4<>"",V4<=TODAY()),5,3)) -> 3 | AM4: =IF(AH4="Sí",5,2) -> 2 | AY4: =IF(AT4="No",5,1) -> 1 | BH4: =IF(BA4="No",5,1) -> 1 | BQ4: =IF(AL4>0,5,1) -> 1 | BR4: =(AM4*0.3+W4*0.25+BH4*0.15+AY4*0.15+BQ4*0.15) -> 1.8 | BS4: =IF(BR4>=4.5,"Crítico",IF(BR4>=3.5,"Alto",IF(BR4>=2.5,"Medio","Bajo"))) -> Bajo
W5: =IF(U5="Sí",5,IF(AND(V5<>"",V5<=TODAY()),5,3)) -> 3 | AM5: =IF(AH5="Sí",5,2) -> 2 | AY5: =IF(AT5="No",5,1) -> 1 | BH5: =IF(BA5="No",5,1) -> 1 | BQ5: =IF(AL5>0,5,1) -> 1 | BR5: =(AM5*0.3+W5*0.25+BH5*0.15+AY5*0.15+BQ5*0.15) -> 1.8 | BS5: =IF(BR5>=4.5,"Crítico",IF(BR5>=3.5,"Alto",IF(BR5>=2.5,"Medio","Bajo"))) -> Bajo
W6: =IF(U6="Sí",5,IF(AND(V6<>"",V6<=TODAY()),5,3)) -> 3 | AM6: =IF(AH6="Sí",5,2) -> 2 | AY6: =IF(AT6="No",5,1) -> 1 | BH6: =IF(BA6="No",5,1) -> 1 | BQ6: =IF(AL6>0,5,1) -> 1 | BR6: =(AM6*0.3+W6*0.25+BH6*0.15+AY6*0.15+BQ6*0.15) -> 1.8 | BS6: =IF(BR6>=4.5,"Crítico",IF(BR6>=3.5,"Alto",IF(BR6>=2.5,"Medio","Bajo"))) -> Bajo
W7: =IF(U7="Sí",5,IF(AND(V7<>"",V7<=TODAY()),5,3)) -> 3 | AM7: =IF(AH7="Sí",5,2) -> 2 | AY7: =IF(AT7="No",5,1) -> 1 | BH7: =IF(BA7="No",5,1) -> 1 | BQ7: =IF(AL7>0,5,1) -> 1 | BR7: =(AM7*0.3+W7*0.25+BH7*0.15+AY7*0.15+BQ7*0.15) -> 1.8 | BS7: =IF(BR7>=4.5,"Crítico",IF(BR7>=3.5,"Alto",IF(BR7>=2.5,"Medio","Bajo"))) -> Bajo
W8: =IF(U8="Sí",5,IF(AND(V8<>"",V8<=TODAY()),5,3)) -> 3 | AM8: =IF(AH8="Sí",5,2) -> 2 | AY8: =IF(AT8="No",5,1) -> 1 | BH8: =IF(BA8="No",5,1) -> 1 | BQ8: =IF(AL8>0,5,1) -> 1 | BR8: =(AM8*0.3+W8*0.25+BH8*0.15+AY8*0.15+BQ8*0.15) -> 1.8 | BS8: =IF(BR8>=4.5,"Crítico",IF(BR8>=3.5,"Alto",IF(BR8>=2.5,"Medio","Bajo"))) -> Bajo
W9: =IF(U9="Sí",5,IF(AND(V9<>"",V9<=TODAY()),5,3)) -> 3 | AM9: =IF(AH9="Sí",5,2) -> 2 | AY9: =IF(AT9="No",5,1) -> 1 | BH9: =IF(BA9="No",5,1) -> 1 | BQ9: =IF(AL9>0,5,1) -> 1 | BR9: =(AM9*0.3+W9*0.25+BH9*0.15+AY9*0.15+BQ9*0.15) -> 1.8 | BS9: =IF(BR9>=4.5,"Crítico",IF(BR9>=3.5,"Alto",IF(BR9>=2.5,"Medio","Bajo"))) -> Bajo
W10: =IF(U10="Sí",5,IF(AND(V10<>"",V10<=TODAY()),5,3)) -> 3 | AM10: =IF(AH10="Sí",5,2) -> 2 | AY10: =IF(AT10="No",5,1) -> 1 | BH10: =IF(BA10="No",5,1) -> 1 | BQ10: =IF(AL10>0,5,1) -> 1 | BR10: =(AM10*0.3+W10*0.25+BH10*0.15+AY10*0.15+BQ10*0.15) -> 1.8 | BS10: =IF(BR10>=4.5,"Crítico",IF(BR10>=3.5,"Alto",IF(BR10>=2.5,"Medio","Bajo"))) -> Bajo
W11: =IF(U11="Sí",5,IF(AND(V11<>"",V11<=TODAY()),5,3)) -> 3 | AM11: =IF(AH11="Sí",5,2) -> 2 | AY11: =IF(AT11="No",5,1) -> 1 | BH11: =IF(BA11="No",5,1) -> 1 | BQ11: =IF(AL11>0,5,1) -> 1 | BR11: =(AM11*0.3+W11*0.25+BH11*0.15+AY11*0.15+BQ11*0.15) -> 1.8 | BS11: =IF(BR11>=4.5,"Crítico",IF(BR11>=3.5,"Alto",IF(BR11>=2.5,"Medio","Bajo"))) -> Bajo
W12: =IF(U12="Sí",5,IF(AND(V12<>"",V12<=TODAY()),5,3)) -> 3 | AM12: =IF(AH12="Sí",5,2) -> 2 | AY12: =IF(AT12="No",5,1) -> 1 | BH12: =IF(BA12="No",5,1) -> 1 | BQ12: =IF(AL12>0,5,1) -> 1 | BR12: =(AM12*0.3+W12*0.25+BH12*0.15+AY12*0.15+BQ12*0.15) -> 1.8 | BS12: =IF(BR12>=4.5,"Crítico",IF(BR12>=3.5,"Alto",IF(BR12>=2.5,"Medio","Bajo"))) -> Bajo
W13: =IF(U13="Sí",5,IF(AND(V13<>"",V13<=TODAY()),5,3)) -> 3 | AM13: =IF(AH13="Sí",5,2) -> 2 | AY13: =IF(AT13="No",5,1) -> 1 | BH13: =IF(BA13="No",5,1) -> 1 | BQ13: =IF(AL13>0,5,1) -> 1 | BR13: =(AM13*0.3+W13*0.25+BH13*0.15+AY13*0.15+BQ13*0.15) -> 1.8 | BS13: =IF(BR13>=4.5,"Crítico",IF(BR13>=3.5,"Alto",IF(BR13>=2.5,"Medio","Bajo"))) -> Bajo
... W2000: =IF(U2000="Sí",5,IF(AND(V2000<>"",V2000<=TODAY()),5,3)) -> 3 | AM2000: =IF(AH2000="Sí",5,2) -> 2 | AY2000: =IF(AT2000="No",5,1) -> 1 | BH2000: =IF(BA2000="No",5,1) -> 1 | BQ2000: =IF(AL2000>0,5,1) -> 1 | BR2000: =(AM2000*0.3+W2000*0.25+BH2000*0.15+AY2000*0.15+BQ2000*0.15) -> 1.8 | BS2000: =IF(BR2000>=4.5,"Crítico",IF(BR2000>=3.5,"Alto",IF(BR2000>=2.5,"Medio","Bajo"))) -> Bajo

Sheet Instructivo
A1: INSTRUCTIVO DE LLENADO – Inventario Institucional de Sistemas, Versiones e Infraestructura Tecnológica
A3: Proveedor nube: Seleccione el proveedor donde reside la infraestructura principal del sistema. Use N/A si es On-prem.
A4: Frecuencia de respaldos: Indique periodicidad real (Diario/Semanal/Mensual/Trimestral/Bajo Demanda/N/A).
A6: Ejemplo – Listado de componentes open source (Nombre – Versión):
A7: Spring Boot – 2.5.4
A8: Log4j – 2.14.1
A9: OpenSSL – 1.1.1
A11: Nota: Capture siempre versiones. Si desconoce, registre 'Por confirmar' y programe validación técnica.

Sheet Resumen_Ejecutivo
A1: Resumen Ejecutivo – Inventario de Sistemas y Riesgo
A2: Este resumen se alimenta automáticamente del inventario. Útil para titulares y comités.
A4: Total sistemas registrados (con ID): | B4: =COUNTA(Inventario_Sistemas!A2:A2000) -> 0
A6: Distribución por nivel de riesgo (automático): | D6: Porcentaje (sobre total):
A7: Crítico | B7: =COUNTIF(Inventario_Sistemas!BS2:BS2000,"Crítico") -> 0 | D7: % Crítico | E7: =IF($B$4=0,0,B7/$B$4) -> 0
A8: Alto | B8: =COUNTIF(Inventario_Sistemas!BS2:BS2000,"Alto") -> 0 | D8: % Alto | E8: =IF($B$4=0,0,B8/$B$4) -> 0
A9: Medio | B9: =COUNTIF(Inventario_Sistemas!BS2:BS2000,"Medio") -> 0 | D9: % Medio | E9: =IF($B$4=0,0,B9/$B$4) -> 0
A10: Bajo | B10: =COUNTIF(Inventario_Sistemas!BS2:BS2000,"Bajo") -> 1999 | D10: % Bajo | E10: =IF($B$4=0,0,B10/$B$4) -> 0
A12: Promedio Score total: | B12: =IF($B$4=0,0,AVERAGEIF(Inventario_Sistemas!BR2:BR2000,">0")) -> 0
A14: Top recomendación:
A15: Ordenar la hoja 'Inventario_Sistemas' por 'Score total' descendente para priorizar remediación (Crítico/Alto).
A16: Adicionalmente, filtrar por '¿Componentes EOL?'='Sí' y '¿Expuesto a Internet?'='Sí'.
A18: Priorización por dependencia (Crítico+Alto):
A19: Dependencia / Entidad | B19: Crítico+Alto (Auto) | C19: Total sistemas
B20: =IF(A20="","",COUNTIFS(Inventario_Sistemas!D2:D2000,A20,Inventario_Sistemas!BS2:BS2000,"Crítico")+COUNTIFS(Inventario_Sistemas!D2:D2000,A20,Inventario_Sistemas!BS2:BS2000,"Alto")) | C20: =IF(A20="","",COUNTIF(Inventario_Sistemas!D2:D2000,A20))
B21: =IF(A21="","",COUNTIFS(Inventario_Sistemas!D2:D2000,A21,Inventario_Sistemas!BS2:BS2000,"Crítico")+COUNTIFS(Inventario_Sistemas!D2:D2000,A21,Inventario_Sistemas!BS2:BS2000,"Alto")) | C21: =IF(A21="","",COUNTIF(Inventario_Sistemas!D2:D2000,A21))
B22: =IF(A22="","",COUNTIFS(Inventario_Sistemas!D2:D2000,A22,Inventario_Sistemas!BS2:BS2000,"Crítico")+COUNTIFS(Inventario_Sistemas!D2:D2000,A22,Inventario_Sistemas!BS2:BS2000,"Alto")) | C22: =IF(A22="","",COUNTIF(Inventario_Sistemas!D2:D2000,A22))
B23: =IF(A23="","",COUNTIFS(Inventario_Sistemas!D2:D2000,A23,Inventario_Sistemas!BS2:BS2000,"Crítico")+COUNTIFS(Inventario_Sistemas!D2:D2000,A23,Inventario_Sistemas!BS2:BS2000,"Alto")) | C23: =IF(A23="","",COUNTIF(Inventario_Sistemas!D2:D2000,A23))
B24: =IF(A24="","",COUNTIFS(Inventario_Sistemas!D2:D2000,A24,Inventario_Sistemas!BS2:BS2000,"Crítico")+COUNTIFS(Inventario_Sistemas!D2:D2000,A24,Inventario_Sistemas!BS2:BS2000,"Alto")) | C24: =IF(A24="","",COUNTIF(Inventario_Sistemas!D2:D2000,A24))
B25: =IF(A25="","",COUNTIFS(Inventario_Sistemas!D2:D2000,A25,Inventario_Sistemas!BS2:BS2000,"Crítico")+COUNTIFS(Inventario_Sistemas!D2:D2000,A25,Inventario_Sistemas!BS2:BS2000,"Alto")) | C25: =IF(A25="","",COUNTIF(Inventario_Sistemas!D2:D2000,A25))
B26: =IF(A26="","",COUNTIFS(Inventario_Sistemas!D2:D2000,A26,Inventario_Sistemas!BS2:BS2000,"Crítico")+COUNTIFS(Inventario_Sistemas!D2:D2000,A26,Inventario_Sistemas!BS2:BS2000,"Alto")) | C26: =IF(A26="","",COUNTIF(Inventario_Sistemas!D2:D2000,A26))
B27: =IF(A27="","",COUNTIFS(Inventario_Sistemas!D2:D2000,A27,Inventario_Sistemas!BS2:BS2000,"Crítico")+COUNTIFS(Inventario_Sistemas!D2:D2000,A27,Inventario_Sistemas!BS2:BS2000,"Alto")) | C27: =IF(A27="","",COUNTIF(Inventario_Sistemas!D2:D2000,A27))
B28: =IF(A28="","",COUNTIFS(Inventario_Sistemas!D2:D2000,A28,Inventario_Sistemas!BS2:BS2000,"Crítico")+COUNTIFS(Inventario_Sistemas!D2:D2000,A28,Inventario_Sistemas!BS2:BS2000,"Alto")) | C28: =IF(A28="","",COUNTIF(Inventario_Sistemas!D2:D2000,A28))
B29: =IF(A29="","",COUNTIFS(Inventario_Sistemas!D2:D2000,A29,Inventario_Sistemas!BS2:BS2000,"Crítico")+COUNTIFS(Inventario_Sistemas!D2:D2000,A29,Inventario_Sistemas!BS2:BS2000,"Alto")) | C29: =IF(A29="","",COUNTIF(Inventario_Sistemas!D2:D2000,A29))
B30: =IF(A30="","",COUNTIFS(Inventario_Sistemas!D2:D2000,A30,Inventario_Sistemas!BS2:BS2000,"Crítico")+COUNTIFS(Inventario_Sistemas!D2:D2000,A30,Inventario_Sistemas!BS2:BS2000,"Alto")) | C30: =IF(A30="","",COUNTIF(Inventario_Sistemas!D2:D2000,A30))
B31: =IF(A31="","",COUNTIFS(Inventario_Sistemas!D2:D2000,A31,Inventario_Sistemas!BS2:BS2000,"Crítico")+COUNTIFS(Inventario_Sistemas!D2:D2000,A31,Inventario_Sistemas!BS2:BS2000,"Alto")) | C31: =IF(A31="","",COUNTIF(Inventario_Sistemas!D2:D2000,A31))
B32: =IF(A32="","",COUNTIFS(Inventario_Sistemas!D2:D2000,A32,Inventario_Sistemas!BS2:BS2000,"Crítico")+COUNTIFS(Inventario_Sistemas!D2:D2000,A32,Inventario_Sistemas!BS2:BS2000,"Alto")) | C32: =IF(A32="","",COUNTIF(Inventario_Sistemas!D2:D2000,A32))
B33: =IF(A33="","",COUNTIFS(Inventario_Sistemas!D2:D2000,A33,Inventario_Sistemas!BS2:BS2000,"Crítico")+COUNTIFS(Inventario_Sistemas!D2:D2000,A33,Inventario_Sistemas!BS2:BS2000,"Alto")) | C33: =IF(A33="","",COUNTIF(Inventario_Sistemas!D2:D2000,A33))
B34: =IF(A34="","",COUNTIFS(Inventario_Sistemas!D2:D2000,A34,Inventario_Sistemas!BS2:BS2000,"Crítico")+COUNTIFS(Inventario_Sistemas!D2:D2000,A34,Inventario_Sistemas!BS2:BS2000,"Alto")) | C34: =IF(A34="","",COUNTIF(Inventario_Sistemas!D2:D2000,A34))
B35: =IF(A35="","",COUNTIFS(Inventario_Sistemas!D2:D2000,A35,Inventario_Sistemas!BS2:BS2000,"Crítico")+COUNTIFS(Inventario_Sistemas!D2:D2000,A35,Inventario_Sistemas!BS2:BS2000,"Alto")) | C35: =IF(A35="","",COUNTIF(Inventario_Sistemas!D2:D2000,A35))
B36: =IF(A36="","",COUNTIFS(Inventario_Sistemas!D2:D2000,A36,Inventario_Sistemas!BS2:BS2000,"Crítico")+COUNTIFS(Inventario_Sistemas!D2:D2000,A36,Inventario_Sistemas!BS2:BS2000,"Alto")) | C36: =IF(A36="","",COUNTIF(Inventario_Sistemas!D2:D2000,A36))
B37: =IF(A37="","",COUNTIFS(Inventario_Sistemas!D2:D2000,A37,Inventario_Sistemas!BS2:BS2000,"Crítico")+COUNTIFS(Inventario_Sistemas!D2:D2000,A37,Inventario_Sistemas!BS2:BS2000,"Alto")) | C37: =IF(A37="","",COUNTIF(Inventario_Sistemas!D2:D2000,A37))
B38: =IF(A38="","",COUNTIFS(Inventario_Sistemas!D2:D2000,A38,Inventario_Sistemas!BS2:BS2000,"Crítico")+COUNTIFS(Inventario_Sistemas!D2:D2000,A38,Inventario_Sistemas!BS2:BS2000,"Alto")) | C38: =IF(A38="","",COUNTIF(Inventario_Sistemas!D2:D2000,A38))
B39: =IF(A39="","",COUNTIFS(Inventario_Sistemas!D2:D2000,A39,Inventario_Sistemas!BS2:BS2000,"Crítico")+COUNTIFS(Inventario_Sistemas!D2:D2000,A39,Inventario_Sistemas!BS2:BS2000,"Alto")) | C39: =IF(A39="","",COUNTIF(Inventario_Sistemas!D2:D2000,A39))
B40: =IF(A40="","",COUNTIFS(Inventario_Sistemas!D2:D2000,A40,Inventario_Sistemas!BS2:BS2000,"Crítico")+COUNTIFS(Inventario_Sistemas!D2:D2000,A40,Inventario_Sistemas!BS2:BS2000,"Alto")) | C40: =IF(A40="","",COUNTIF(Inventario_Sistemas!D2:D2000,A40))
B41: =IF(A41="","",COUNTIFS(Inventario_Sistemas!D2:D2000,A41,Inventario_Sistemas!BS2:BS2000,"Crítico")+COUNTIFS(Inventario_Sistemas!D2:D2000,A41,Inventario_Sistemas!BS2:BS2000,"Alto")) | C41: =IF(A41="","",COUNTIF(Inventario_Sistemas!D2:D2000,A41))
B42: =IF(A42="","",COUNTIFS(Inventario_Sistemas!D2:D2000,A42,Inventario_Sistemas!BS2:BS2000,"Crítico")+COUNTIFS(Inventario_Sistemas!D2:D2000,A42,Inventario_Sistemas!BS2:BS2000,"Alto")) | C42: =IF(A42="","",COUNTIF(Inventario_Sistemas!D2:D2000,A42))
B43: =IF(A43="","",COUNTIFS(Inventario_Sistemas!D2:D2000,A43,Inventario_Sistemas!BS2:BS2000,"Crítico")+COUNTIFS(Inventario_Sistemas!D2:D2000,A43,Inventario_Sistemas!BS2:BS2000,"Alto")) | C43: =IF(A43="","",COUNTIF(Inventario_Sistemas!D2:D2000,A43))
B44: =IF(A44="","",COUNTIFS(Inventario_Sistemas!D2:D2000,A44,Inventario_Sistemas!BS2:BS2000,"Crítico")+COUNTIFS(Inventario_Sistemas!D2:D2000,A44,Inventario_Sistemas!BS2:BS2000,"Alto")) | C44: =IF(A44="","",COUNTIF(Inventario_Sistemas!D2:D2000,A44))
B45: =IF(A45="","",COUNTIFS(Inventario_Sistemas!D2:D2000,A45,Inventario_Sistemas!BS2:BS2000,"Crítico")+COUNTIFS(Inventario_Sistemas!D2:D2000,A45,Inventario_Sistemas!BS2:BS2000,"Alto")) | C45: =IF(A45="","",COUNTIF(Inventario_Sistemas!D2:D2000,A45))
...

Sheet Catálogos
A1: Sí/No | B1: Clasificación | C1: TipoSistema | D1: Ambiente | E1: Lenguaje | F1: Framework | G1: BD | H1: SO | I1: WebServer | J1: AuthTipo | K1: InfraTipo | L1: NubeProveedor | M1: FreqBackup | N1: Declaratoria
A2: Sí | B2: Crítico | C2: Web | D2: Prod | E2: Java | F2: Spring | G2: Oracle | H2: Windows Server | I2: IIS | J2: MFA | K2: On-prem | L2: AWS | M2: Diario | N2: Declaro bajo protesta que la información es veraz
A3: No | B3: Alto | C3: Legado | D3: Preprod | E3: .NET | F3: .NET Core | G3: SQL Server | H3: Linux | I3: Apache | J3: AD | K3: Nube pública | L3: Azure | M3: Semanal | N3: No declaro (pendiente firma)
B4: Medio | C4: Base de datos | D4: Dev | E4: PHP | F4: Laravel | G4: MySQL | H4: AIX | I4: Nginx | J4: OAuth | K4: Híbrido | L4: GCP | M4: Mensual
B5: Bajo | C5: API | D5: Otro | E5: Python | F5: Django | G5: PostgreSQL | H5: Solaris | I5: Tomcat | J5: SAML | K5: Nacional | L5: Oracle Cloud | M5: Trimestral
C6: Móvil | E6: Node | F6: Flask | G6: MongoDB | H6: Otro | I6: JBoss/WildFly | J6: Usuario/Contraseña | K6: N/A | L6: Nube Nacional | M6: Bajo Demanda
C7: Otro | E7: COBOL | F7: Angular | G7: DB2 | H7: WebLogic | I7: WebLogic | J7: Otro | K7: Otro | L7: Otro | M7: N/A
E8: Go | F8: React | G8: Otro | H8: WebSphere | I8: WebSphere | J8: N/A | L8: N/A | M8: React
E9: Ruby | F9: Vue | G9: N/A | H9: Otro | I9: Otro | M9: Vue
E10: Otro | F10: Express | H10: N/A | I10: N/A | M10: Express
F11: Ruby on Rails | M11: Ruby on Rails
F12: Struts | M12: Struts
F13: JSF | M13: JSF
F14: Otro | M14: Otro
F15: N/A | M15: N/A

Sheet Ponderación
A1: Factor | B1: Peso
A2: Exposición pública | B2: 0.3
A3: Componentes EOL/Soporte | B3: 0.25
A4: Sin MFA | B4: 0.15
A5: Sin respaldo | B5: 0.15
A6: Vuln críticas | B6: 0.15
